<mujoco model="X7S">

  <compiler angle="radian" meshdir="meshes" eulerseq="zyx" autolimits="true" />

  <default>
    <joint limited="true" damping="0.01" armature="0.01" frictionloss="0.01" />
    <geom condim="4" contype="1" conaffinity="15" friction="0.9 0.2 0.2" solref="0.001 2" />
    <motor ctrllimited="true" />
    <equality solref="0.001 2" />
    <default class="visualgeom">
      <geom material="visualgeom" condim="1" contype="0" conaffinity="0" />
    </default>
  </default>

  <asset>
    <mesh name="base_link" file="base_link.STL" />
    <mesh name="link1" file="link1.STL" />
    <mesh name="link2" file="link2.STL" />
    <mesh name="link3" file="link3.STL" />
    <mesh name="link4" file="link4.STL" />
    <mesh name="link5" file="link5.STL" />
    <mesh name="link6" file="link6.STL" />
    <mesh name="link7" file="link7.STL" />
    <mesh name="link8" file="link8.STL" />
    <mesh name="link9" file="link9.STL" />
    <mesh name="link10" file="link10.STL" />
    <mesh name="link11" file="link11.STL" />
    <mesh name="link12" file="link12.STL" />
    <mesh name="link13" file="link13.STL" />
    <mesh name="link14" file="link14.STL" />
    <mesh name="link15" file="link15.STL" />
    <mesh name="link16" file="link16.STL" />
    <mesh name="link17" file="link17.STL" />
    <mesh name="link18" file="link18.STL" />
    <mesh name="link19" file="link19.STL" />
    <mesh name="link20" file="link20.STL" />
    <mesh name="link21" file="link21.STL" />
    <mesh name="link22" file="link22.STL" />
    <texture name="texplane" type="2d" builtin="checker" rgb1=".0 .0 .0" rgb2=".8 .8 .8" width="100" height="100" />
    <material name="matplane" reflectance="0." texture="texplane" texrepeat="1 1" texuniform="true" />
    <material name="visualgeom" rgba="0.5 0.9 0.2 1" />
  </asset>

  <worldbody>
    <camera name="fixed" pos="0 -3.0 1.0662300581031923" xyaxes="1 0 0 0 0 1" />
    <camera name="track" mode="trackcom" pos="0 -3.0 1.0662300581031923" xyaxes="1 0 0 0 0 1" />
    <body name="root" pos="0 0 0.05">
      <site name="imu" size="0.01" pos="0 0 0" />
      <geom type="mesh" rgba="0.89804 0.91765 0.92941 1" mesh="base_link" contype="1" conaffinity="0" density="0" group="1" class="visualgeom" />
      <geom type="mesh" rgba="0.89804 0.91765 0.92941 1" mesh="base_link" />
      <body name="link1" pos="0.096 0 0.31">
        <inertial pos="-0.010805 -0.00069779 -0.059694" quat="-0.00891618 0.69214 -0.00707077 0.721673" mass="6.205" diaginertia="0.0672963 0.0603866 0.019857" />
        <joint name="joint1" pos="0 0 0" axis="0 0 1" type="slide" range="0 0.54" actuatorfrcrange="-100 100" />
        <geom type="mesh" rgba="1 1 1 1" mesh="link1" contype="1" conaffinity="0" density="0" group="1" class="visualgeom" />
        <geom type="mesh" rgba="1 1 1 1" mesh="link1" />
        <body name="link2" pos="0.066 -0.0546 -0.06">
          <inertial pos="-0.000779579 0.0537606 0.220464" quat="0.999969 0.00781611 0.000496861 -4.07465e-05" mass="3.01263" diaginertia="0.03987 0.0346161 0.00966387" />
          <joint name="joint2" pos="0 0 0" axis="0 -1 0" range="-10 10" actuatorfrcrange="-100 100" />
          <geom type="mesh" rgba="0.898039 0.917647 0.929412 1" mesh="link2" contype="1" conaffinity="0" density="0" group="1" class="visualgeom" />
          <geom type="mesh" rgba="0.898039 0.917647 0.929412 1" mesh="link2" />
          <body name="link3" pos="0 0.0544 0.356">
            <inertial pos="-1.21665e-08 0.000155101 0.0414775" quat="0.998125 -0.0612064 0 0" mass="0.429407" diaginertia="0.00027 0.000261231 0.000178769" />
            <joint name="joint3" pos="0 0 0" axis="0 0 1" range="-10 10" actuatorfrcrange="-100 100" />
            <geom type="mesh" rgba="0.898039 0.917647 0.929412 1" mesh="link3" contype="1" conaffinity="0" density="0" group="1" class="visualgeom" />
            <geom type="mesh" rgba="0.898039 0.917647 0.929412 1" mesh="link3" />
            <body name="link4" pos="0 -0.025 0.049">
              <inertial pos="0.0145475 0.0229595 0.0787914" quat="0.554609 0.487433 -0.484186 0.469448" mass="1.5442" diaginertia="0.0077037 0.00575032 0.00475598" />
              <joint name="joint4" pos="0 0 0" axis="0 -1 0" range="-10 10" actuatorfrcrange="-100 100" />
              <geom type="mesh" rgba="0.898039 0.917647 0.929412 1" mesh="link4" contype="1" conaffinity="0" density="0" group="1" class="visualgeom" />
              <geom type="mesh" rgba="0.898039 0.917647 0.929412 1" mesh="link4" />
            </body>
          </body>
          <body name="link5" pos="0 0.1424 0.28">
            <inertial pos="0.0203119 0.0282075 -0.000172804" quat="0.674894 0.674894 0.210994 0.210994" mass="0.131892" diaginertia="0.00014772 0.00014 6.228e-05" />
            <joint name="joint5" pos="0 0 0" axis="0 1 0" range="-10 10" actuatorfrcrange="-100 100" />
            <geom type="mesh" rgba="0.898039 0.917647 0.929412 1" mesh="link5" contype="1" conaffinity="0" density="0" group="1" class="visualgeom" />
            <geom type="mesh" rgba="0.898039 0.917647 0.929412 1" mesh="link5" />
            <body name="link6" pos="0.02725 0.063 0">
              <inertial pos="-0.0244519 0.0044012 -0.0251862" quat="0.939496 0.0137573 -0.0501379 0.338591" mass="1.03162" diaginertia="0.00170434 0.00163464 0.000871019" />
              <joint name="joint6" pos="0 0 0" axis="-1 0 0" range="-10 10" actuatorfrcrange="-100 100" />
              <geom type="mesh" rgba="0.898039 0.917647 0.929412 1" mesh="link6" contype="1" conaffinity="0" density="0" group="1" class="visualgeom" />
              <geom type="mesh" rgba="0.898039 0.917647 0.929412 1" mesh="link6" />
              <body name="link7" pos="-0.02725 0 -0.0865">
                <inertial pos="0.000827778 -0.00148365 -0.105295" quat="0.804799 -0.0062907 -0.0282848 0.59284" mass="0.736099" diaginertia="0.0023016 0.00229412 0.000594285" />
                <joint name="joint7" pos="0 0 0" axis="0 0 -1" range="-10 10" actuatorfrcrange="-100 100" />
                <geom type="mesh" rgba="0.898039 0.917647 0.929412 1" mesh="link7" contype="1" conaffinity="0" density="0" group="1" class="visualgeom" />
                <geom type="mesh" rgba="0.898039 0.917647 0.929412 1" mesh="link7" />
                <body name="link8" pos="0 -0.02725 -0.1435">
                  <inertial pos="0.0593724 0.0253236 -0.012597" quat="0.00796675 0.620313 -0.0947329 0.778571" mass="0.487507" diaginertia="0.00070775 0.000552568 0.000379682" />
                  <joint name="joint8" pos="0 0 0" axis="0 -1 0" range="-10 10" actuatorfrcrange="-100 100" />
                  <geom type="mesh" rgba="0.898039 0.917647 0.929412 1" mesh="link8" contype="1" conaffinity="0" density="0" group="1" class="visualgeom" />
                  <geom type="mesh" rgba="0.898039 0.917647 0.929412 1" mesh="link8" />
                  <body name="link9" pos="0.0945 0.02725 -0.015">
                    <inertial pos="0.0458969 -0.000535553 -9.66306e-05" quat="0 0.707107 0 0.707107" mass="0.487432" diaginertia="0.00029 0.00027 0.00024" />
                    <joint name="joint9" pos="0 0 0" axis="1 0 0" range="-10 10" actuatorfrcrange="-100 100" />
                    <geom type="mesh" rgba="0.898039 0.917647 0.929412 1" mesh="link9" contype="1" conaffinity="0" density="0" group="1" class="visualgeom" />
                    <geom type="mesh" rgba="0.898039 0.917647 0.929412 1" mesh="link9" />
                    <body name="link10" pos="0.05 -0.02725 0">
                      <inertial pos="0.0575036 0.0264951 0.00135889" quat="0.0626958 0.658169 -0.0940555 0.744336" mass="0.432944" diaginertia="0.000412537 0.000334457 0.000243007" />
                      <joint name="joint10" pos="0 0 0" axis="0 -1 0" range="-10 10" actuatorfrcrange="-100 100" />
                      <geom type="mesh" rgba="0.898039 0.917647 0.929412 1" mesh="link10" contype="1" conaffinity="0" density="0" group="1" class="visualgeom" />
                      <geom type="mesh" rgba="0.898039 0.917647 0.929412 1" mesh="link10" />
                      <body name="link11" pos="0.066 0.02725 -0.022">
                        <inertial pos="0.0782375 2.27689e-05 0.0203908" quat="0 0.784141 0 0.620583" mass="0.471848" diaginertia="0.000654164 0.00043 0.000385836" />
                        <joint name="joint11" pos="0 0 0" axis="0 0 -1" range="-10 10" actuatorfrcrange="-100 100" />
                        <geom type="mesh" rgba="0.898039 0.917647 0.929412 1" mesh="link11" contype="1" conaffinity="0" density="0" group="1" class="visualgeom" />
                        <geom type="mesh" rgba="0.898039 0.917647 0.929412 1" mesh="link11" />
                        <body name="link12" pos="0.12737 0.024896 0.021756">
                          <inertial pos="-0.000355223 -0.00782704 -0.00298832" quat="0.5 0.5 0.5 0.5" mass="0.0647982" diaginertia="3e-05 3e-05 2e-05" />
                          <joint name="joint12" pos="0 0 0" axis="0 1 0" type="slide" range="0 0.044" actuatorfrcrange="-100 100" />
                          <geom type="mesh" rgba="1 1 1 1" mesh="link12" contype="1" conaffinity="0" density="0" group="1" class="visualgeom" />
                          <geom type="mesh" rgba="1 1 1 1" mesh="link12" />
                        </body>
                        <body name="link13" pos="0.12737 -0.0249 0.021756">
                          <inertial pos="-0.000355223 0.00782769 0.00242006" quat="0.5 0.5 0.5 0.5" mass="0.0647982" diaginertia="3e-05 3e-05 2e-05" />
                          <joint name="joint13" pos="0 0 0" axis="0 -1 0" type="slide" range="0 0.044" actuatorfrcrange="-100 100" />
                          <geom type="mesh" rgba="1 1 1 1" mesh="link13" contype="1" conaffinity="0" density="0" group="1" class="visualgeom" />
                          <geom type="mesh" rgba="1 1 1 1" mesh="link13" />
                        </body>
                      </body>
                    </body>
                  </body>
                </body>
              </body>
            </body>
          </body>
          <body name="link14" pos="0 -0.0336 0.28">
            <inertial pos="0.0203119 -0.0282075 -0.000172804" quat="0.674894 0.674894 -0.210994 -0.210994" mass="0.131892" diaginertia="0.00014772 0.00014 6.228e-05" />
            <joint name="joint14" pos="0 0 0" axis="0 -1 0" range="-10 10" actuatorfrcrange="-100 100" />
            <geom type="mesh" rgba="0.898039 0.917647 0.929412 1" mesh="link14" contype="1" conaffinity="0" density="0" group="1" class="visualgeom" />
            <geom type="mesh" rgba="0.898039 0.917647 0.929412 1" mesh="link14" />
            <body name="link15" pos="0.02725 -0.063 0">
              <inertial pos="-0.0244519 -0.00440118 -0.0251861" quat="0.939496 -0.0137573 -0.0501379 -0.338591" mass="1.03162" diaginertia="0.00170434 0.00163464 0.000871019" />
              <joint name="joint15" pos="0 0 0" axis="-1 0 0" range="-10 10" actuatorfrcrange="-100 100" />
              <geom type="mesh" rgba="0.898039 0.917647 0.929412 1" mesh="link15" contype="1" conaffinity="0" density="0" group="1" class="visualgeom" />
              <geom type="mesh" rgba="0.898039 0.917647 0.929412 1" mesh="link15" />
              <body name="link16" pos="-0.02725 0 -0.0865">
                <inertial pos="0.00082778 0.00148435 -0.105295" quat="0.59284 -0.0282848 -0.0062907 0.804799" mass="0.736099" diaginertia="0.0023016 0.00229412 0.000594285" />
                <joint name="joint16" pos="0 0 0" axis="0 0 -1" range="-10 10" actuatorfrcrange="-100 100" />
                <geom type="mesh" rgba="0.898039 0.917647 0.929412 1" mesh="link16" contype="1" conaffinity="0" density="0" group="1" class="visualgeom" />
                <geom type="mesh" rgba="0.898039 0.917647 0.929412 1" mesh="link16" />
                <body name="link17" pos="0 0.02725 -0.1435">
                  <inertial pos="0.0593724 -0.0253233 -0.0127287" quat="-0.00796675 0.620313 0.0947329 0.778571" mass="0.487507" diaginertia="0.00070775 0.000552568 0.000379682" />
                  <joint name="joint17" pos="0 0 0" axis="0 1 0" range="-10 10" actuatorfrcrange="-100 100" />
                  <geom type="mesh" rgba="0.898039 0.917647 0.929412 1" mesh="link17" contype="1" conaffinity="0" density="0" group="1" class="visualgeom" />
                  <geom type="mesh" rgba="0.898039 0.917647 0.929412 1" mesh="link17" />
                  <body name="link18" pos="0.0945 -0.02725 -0.015">
                    <inertial pos="0.045897 0.000535553 -2.35789e-05" quat="0 0.707107 0 0.707107" mass="0.487432" diaginertia="0.00029 0.00027 0.00024" />
                    <joint name="joint18" pos="0 0 0" axis="1 0 0" range="-10 10" actuatorfrcrange="-100 100" />
                    <geom type="mesh" rgba="0.898039 0.917647 0.929412 1" mesh="link18" contype="1" conaffinity="0" density="0" group="1" class="visualgeom" />
                    <geom type="mesh" rgba="0.898039 0.917647 0.929412 1" mesh="link18" />
                    <body name="link19" pos="0.05 0.02725 0">
                      <inertial pos="0.0575036 -0.0265307 0.00135892" quat="-0.0626958 0.658169 0.0940555 0.744336" mass="0.432944" diaginertia="0.000412537 0.000334457 0.000243007" />
                      <joint name="joint19" pos="0 0 0" axis="0 1 0" range="-10 10" actuatorfrcrange="-100 100" />
                      <geom type="mesh" rgba="0.898039 0.917647 0.929412 1" mesh="link19" contype="1" conaffinity="0" density="0" group="1" class="visualgeom" />
                      <geom type="mesh" rgba="0.898039 0.917647 0.929412 1" mesh="link19" />
                      <body name="link20" pos="0.066 -0.02725 -0.022">
                        <inertial pos="0.0782375 2.27689e-05 0.0203908" quat="0 0.784141 0 0.620583" mass="0.471848" diaginertia="0.000654164 0.00043 0.000385836" />
                        <joint name="joint20" pos="0 0 0" axis="0 0 -1" range="-10 10" actuatorfrcrange="-100 100" />
                        <geom type="mesh" rgba="0.898039 0.917647 0.929412 1" mesh="link20" contype="1" conaffinity="0" density="0" group="1" class="visualgeom" />
                        <geom type="mesh" rgba="0.898039 0.917647 0.929412 1" mesh="link20" />
                        <body name="link21" pos="0.12737 0.024896 0.021756">
                          <inertial pos="-0.000355223 -0.00782704 -0.00298832" quat="0.5 0.5 0.5 0.5" mass="0.0647982" diaginertia="3e-05 3e-05 2e-05" />
                          <joint name="joint21" pos="0 0 0" axis="0 1 0" type="slide" range="0 0.044" actuatorfrcrange="-100 100" />
                          <geom type="mesh" rgba="1 1 1 1" mesh="link21" contype="1" conaffinity="0" density="0" group="1" class="visualgeom" />
                          <geom type="mesh" rgba="1 1 1 1" mesh="link21" />
                        </body>
                        <body name="link22" pos="0.12737 -0.0249 0.021756">
                          <inertial pos="-0.000355223 0.00782769 0.00242006" quat="0.5 0.5 0.5 0.5" mass="0.0647982" diaginertia="3e-05 3e-05 2e-05" />
                          <joint name="joint22" pos="0 0 0" axis="0 -1 0" type="slide" range="0 0.044" actuatorfrcrange="-100 100" />
                          <geom type="mesh" rgba="0.898039 0.917647 0.929412 1" mesh="link22" contype="1" conaffinity="0" density="0" group="1" class="visualgeom" />
                          <geom type="mesh" rgba="0.898039 0.917647 0.929412 1" mesh="link22" />
                        </body>
                      </body>
                    </body>
                  </body>
                </body>
              </body>
            </body>
          </body>
        </body>
      </body>
    </body>
  </worldbody>

  <actuator>
    <motor name="joint1" joint="joint1" ctrllimited="true" ctrlrange="-100 100" gear="1" />
    <motor name="joint2" joint="joint2" ctrllimited="true" ctrlrange="-100 100" gear="1" />
    <motor name="joint3" joint="joint3" ctrllimited="true" ctrlrange="-100 100" gear="1" />
    <motor name="joint4" joint="joint4" ctrllimited="true" ctrlrange="-100 100" gear="1" />
    <motor name="joint5" joint="joint5" ctrllimited="true" ctrlrange="-100 100" gear="1" />
    <motor name="joint6" joint="joint6" ctrllimited="true" ctrlrange="-100 100" gear="1" />
    <motor name="joint7" joint="joint7" ctrllimited="true" ctrlrange="-100 100" gear="1" />
    <motor name="joint8" joint="joint8" ctrllimited="true" ctrlrange="-100 100" gear="1" />
    <motor name="joint9" joint="joint9" ctrllimited="true" ctrlrange="-100 100" gear="1" />
    <motor name="joint10" joint="joint10" ctrllimited="true" ctrlrange="-100 100" gear="1" />
    <motor name="joint11" joint="joint11" ctrllimited="true" ctrlrange="-100 100" gear="1" />
    <motor name="joint12" joint="joint12" ctrllimited="true" ctrlrange="-100 100" gear="1" />
    <motor name="joint13" joint="joint13" ctrllimited="true" ctrlrange="-100 100" gear="1" />
    <motor name="joint14" joint="joint14" ctrllimited="true" ctrlrange="-100 100" gear="1" />
    <motor name="joint15" joint="joint15" ctrllimited="true" ctrlrange="-100 100" gear="1" />
    <motor name="joint16" joint="joint16" ctrllimited="true" ctrlrange="-100 100" gear="1" />
    <motor name="joint17" joint="joint17" ctrllimited="true" ctrlrange="-100 100" gear="1" />
    <motor name="joint18" joint="joint18" ctrllimited="true" ctrlrange="-100 100" gear="1" />
    <motor name="joint19" joint="joint19" ctrllimited="true" ctrlrange="-100 100" gear="1" />
    <motor name="joint20" joint="joint20" ctrllimited="true" ctrlrange="-100 100" gear="1" />
    <motor name="joint21" joint="joint21" ctrllimited="true" ctrlrange="-100 100" gear="1" />
    <motor name="joint22" joint="joint22" ctrllimited="true" ctrlrange="-100 100" gear="1" />
  </actuator>

  <sensor>
    <actuatorpos name="joint1_p" actuator="joint1" />
    <actuatorvel name="joint1_v" actuator="joint1" />
    <actuatorfrc name="joint1_f" actuator="joint1" noise="0.001" />
    <actuatorpos name="joint2_p" actuator="joint2" />
    <actuatorvel name="joint2_v" actuator="joint2" />
    <actuatorfrc name="joint2_f" actuator="joint2" noise="0.001" />
    <actuatorpos name="joint3_p" actuator="joint3" />
    <actuatorvel name="joint3_v" actuator="joint3" />
    <actuatorfrc name="joint3_f" actuator="joint3" noise="0.001" />
    <actuatorpos name="joint4_p" actuator="joint4" />
    <actuatorvel name="joint4_v" actuator="joint4" />
    <actuatorfrc name="joint4_f" actuator="joint4" noise="0.001" />
    <actuatorpos name="joint5_p" actuator="joint5" />
    <actuatorvel name="joint5_v" actuator="joint5" />
    <actuatorfrc name="joint5_f" actuator="joint5" noise="0.001" />
    <actuatorpos name="joint6_p" actuator="joint6" />
    <actuatorvel name="joint6_v" actuator="joint6" />
    <actuatorfrc name="joint6_f" actuator="joint6" noise="0.001" />
    <actuatorpos name="joint7_p" actuator="joint7" />
    <actuatorvel name="joint7_v" actuator="joint7" />
    <actuatorfrc name="joint7_f" actuator="joint7" noise="0.001" />
    <actuatorpos name="joint8_p" actuator="joint8" />
    <actuatorvel name="joint8_v" actuator="joint8" />
    <actuatorfrc name="joint8_f" actuator="joint8" noise="0.001" />
    <actuatorpos name="joint9_p" actuator="joint9" />
    <actuatorvel name="joint9_v" actuator="joint9" />
    <actuatorfrc name="joint9_f" actuator="joint9" noise="0.001" />
    <actuatorpos name="joint10_p" actuator="joint10" />
    <actuatorvel name="joint10_v" actuator="joint10" />
    <actuatorfrc name="joint10_f" actuator="joint10" noise="0.001" />
    <actuatorpos name="joint11_p" actuator="joint11" />
    <actuatorvel name="joint11_v" actuator="joint11" />
    <actuatorfrc name="joint11_f" actuator="joint11" noise="0.001" />
    <actuatorpos name="joint12_p" actuator="joint12" />
    <actuatorvel name="joint12_v" actuator="joint12" />
    <actuatorfrc name="joint12_f" actuator="joint12" noise="0.001" />
    <actuatorpos name="joint13_p" actuator="joint13" />
    <actuatorvel name="joint13_v" actuator="joint13" />
    <actuatorfrc name="joint13_f" actuator="joint13" noise="0.001" />
    <actuatorpos name="joint14_p" actuator="joint14" />
    <actuatorvel name="joint14_v" actuator="joint14" />
    <actuatorfrc name="joint14_f" actuator="joint14" noise="0.001" />
    <actuatorpos name="joint15_p" actuator="joint15" />
    <actuatorvel name="joint15_v" actuator="joint15" />
    <actuatorfrc name="joint15_f" actuator="joint15" noise="0.001" />
    <actuatorpos name="joint16_p" actuator="joint16" />
    <actuatorvel name="joint16_v" actuator="joint16" />
    <actuatorfrc name="joint16_f" actuator="joint16" noise="0.001" />
    <actuatorpos name="joint17_p" actuator="joint17" />
    <actuatorvel name="joint17_v" actuator="joint17" />
    <actuatorfrc name="joint17_f" actuator="joint17" noise="0.001" />
    <actuatorpos name="joint18_p" actuator="joint18" />
    <actuatorvel name="joint18_v" actuator="joint18" />
    <actuatorfrc name="joint18_f" actuator="joint18" noise="0.001" />
    <actuatorpos name="joint19_p" actuator="joint19" />
    <actuatorvel name="joint19_v" actuator="joint19" />
    <actuatorfrc name="joint19_f" actuator="joint19" noise="0.001" />
    <actuatorpos name="joint20_p" actuator="joint20" />
    <actuatorvel name="joint20_v" actuator="joint20" />
    <actuatorfrc name="joint20_f" actuator="joint20" noise="0.001" />
    <actuatorpos name="joint21_p" actuator="joint21" />
    <actuatorvel name="joint21_v" actuator="joint21" />
    <actuatorfrc name="joint21_f" actuator="joint21" noise="0.001" />
    <actuatorpos name="joint22_p" actuator="joint22" />
    <actuatorvel name="joint22_v" actuator="joint22" />
    <actuatorfrc name="joint22_f" actuator="joint22" noise="0.001" />
    <framequat name="orientation" objtype="site" noise="0.001" objname="imu" />
    <gyro name="angular-velocity" site="imu" noise="0.005" cutoff="34.9" />
  </sensor>

  <keyframe>
    <key name="home" qpos="0.4 0 0 0 0 0 0 -1.5 0 0 0 0 0 0 0 0 1.5 0 0 0 0 0"/>
  </keyframe>

</mujoco>
